<?xml version="1.0"?>
<robot xmlns:xacro="http://www.ros.org/wiki/xacro" name="bluetech_robot">


    <!-- This will include all the contents of example_include.xacro first. -->
    <xacro:include filename="basic_macros.xacro" />
    <xacro:include filename="gazebo_control.xacro" />
    <xacro:include filename="ros2_control.xacro" />
    <xacro:include filename="lidar.xacro" />

    <link name="base_footprint" />


    <joint name="base_footprint_to_chassis_link" type="fixed">
        <origin xyz="0 0 0.5" rpy="0 0 0" />
        <parent link="base_footprint" />
        <child link="chassis_link" />
    </joint>

    <link name="chassis_link">
        <visual>
            <origin xyz="0 0 0" rpy="0 0 0" />
            <geometry>
                <box size="2 0.5 0.5" />
            </geometry>
            <material name="green">
                <color rgba="0.2 1 0.2 1" />
            </material>
        </visual>
        <collision>
            <origin xyz="0 0 0" rpy="0 0 0" />
            <geometry>
                <box size="2 0.5 0.5" />
            </geometry>
        </collision>
        <inertial>
            <origin xyz="0 0 0" rpy="0 0 0" />
            <mass value="1.0" />
            <inertia ixx="2.26" ixy="0.0" ixz="0.0" iyy="6.26" iyz="0.0" izz="8.5" />
        </inertial>
    </link>


    <!-- RIGHT WHEEL -->
    <!-- Right Wheel Joint -->
    <joint name="right_wheel_joint" type="revolute">
        <origin xyz="0.75 0 -0.375" rpy="0 0 0" />
        <parent link="chassis_link" />
        <child link="right_wheel_link" />
        <axis xyz="0 0 1" />
        <limit lower='-3140000000' upper='3140000000' velocity="100" effort="100" />
    </joint>

    <!-- Right Wheel Link -->
    <link name="right_wheel_link">
        <visual>
            <origin xyz="0 0 0" rpy="0 0 0" />
            <geometry>
                <cylinder radius="0.5" length="0.25" />
            </geometry>
            <material name="blue" />
        </visual>
        <collision>
            <origin xyz="0 0 0" rpy="0 0 0" />
            <geometry>
                <cylinder radius="0.5" length="0.25" />
            </geometry>
        </collision>
        <xacro:inertial_cylinder mass="0.5" length="0.5" radius="0.25">
            <origin xyz="0 0 0" rpy="1.57 0 1.57" />
        </xacro:inertial_cylinder>
    </link>


    <!-- LEFT WHEEL -->
    <!-- Left Wheel Joint -->
    <joint name="left_wheel_joint" type="revolute">
        <origin xyz="-0.75 0 -0.375" rpy="0 0 0" />
        <parent link="chassis_link" />
        <child link="left_wheel_link" />
        <axis xyz="0 0 1" />
        <limit lower='-3140000000' upper='3140000000' velocity="100" effort="100" />
    </joint>

    <!-- Left Wheel Link -->
    <link name="left_wheel_link">
        <visual>
            <origin xyz="0 0 0" rpy="0 0 0" />
            <geometry>
                <cylinder radius="0.5" length="0.25" />
            </geometry>
            <material name="orange" />
        </visual>
        <collision>
            <origin xyz="0 0 0" rpy="0 0 0" />
            <geometry>
                <cylinder radius="0.5" length="0.25" />
            </geometry>
        </collision>
        <xacro:inertial_cylinder mass="0.5" length="0.5" radius="0.25">
            <origin xyz="0 0 0" rpy="1.57 0 1.57" />
        </xacro:inertial_cylinder>
    </link>


</robot>