<sdf version='1.7'>
  <world name='default'>
    <light name='sun' type='directional'>
      <cast_shadows>1</cast_shadows>
      <pose>0 0 10 0 -0 0</pose>
      <diffuse>0.8 0.8 0.8 1</diffuse>
      <specular>0.2 0.2 0.2 1</specular>
      <attenuation>
        <range>1000</range>
        <constant>0.9</constant>
        <linear>0.01</linear>
        <quadratic>0.001</quadratic>
      </attenuation>
      <direction>-0.5 0.1 -0.9</direction>
      <spot>
        <inner_angle>0</inner_angle>
        <outer_angle>0</outer_angle>
        <falloff>0</falloff>
      </spot>
    </light>
    <model name='ground_plane'>
      <static>1</static>
      <link name='link'>
        <collision name='collision'>
          <geometry>
            <plane>
              <normal>0 0 1</normal>
              <size>100 100</size>
            </plane>
          </geometry>
          <surface>
            <friction>
              <ode>
                <mu>1</mu>
                <mu2>1</mu2>
              </ode>
              <torsional>
                <coefficient>20000</coefficient>
              </torsional>
            </friction>
            <contact>
              <ode/>
            </contact>
            <bounce/>
          </surface>
          <max_contacts>10</max_contacts>
        </collision>
        <visual name='visual'>
          <cast_shadows>0</cast_shadows>
          <geometry>
            <plane>
              <normal>0 0 1</normal>
              <size>100 100</size>
            </plane>
          </geometry>
          <material>
            <script>
              <uri>file://media/materials/scripts/gazebo.material</uri>
              <name>Gazebo/Grey</name>
            </script>
          </material>
        </visual>
        <self_collide>0</self_collide>
        <enable_wind>0</enable_wind>
        <kinematic>0</kinematic>
      </link>
    </model>
    <gravity>0 0 -9.8</gravity>
    <magnetic_field>6e-06 2.3e-05 -4.2e-05</magnetic_field>
    <atmosphere type='adiabatic'/>
    <physics type='ode'>
      <max_step_size>0.001</max_step_size>
      <real_time_factor>1</real_time_factor>
      <real_time_update_rate>1000</real_time_update_rate>
    </physics>
    <scene>
      <ambient>0.4 0.4 0.4 1</ambient>
      <background>0.7 0.7 0.7 1</background>
      <shadows>1</shadows>
    </scene>
    <audio>
      <device>default</device>
    </audio>
    <wind/>
    <spherical_coordinates>
      <surface_model>EARTH_WGS84</surface_model>
      <latitude_deg>0</latitude_deg>
      <longitude_deg>0</longitude_deg>
      <elevation>0</elevation>
      <heading_deg>0</heading_deg>
    </spherical_coordinates>
    <model name='bluetech_robot'>
      <link name='chassis_link'>
        <inertial>
          <pose>0 0 0 0 -0 0</pose>
          <mass>1</mass>
          <inertia>
            <ixx>2.26</ixx>
            <ixy>0</ixy>
            <ixz>0</ixz>
            <iyy>6.26</iyy>
            <iyz>0</iyz>
            <izz>8.5</izz>
          </inertia>
        </inertial>
        <collision name='chassis_link_collision'>
          <pose>0 0 0 0 -0 0</pose>
          <geometry>
            <box>
              <size>2 0.5 0.5</size>
            </box>
          </geometry>
          <surface>
            <contact>
              <ode/>
            </contact>
            <friction>
              <ode/>
              <torsional>
                <ode/>
              </torsional>
            </friction>
            <bounce/>
          </surface>
          <max_contacts>10</max_contacts>
        </collision>
        <visual name='chassis_link_visual'>
          <pose>0 0 0 0 -0 0</pose>
          <geometry>
            <box>
              <size>2 0.5 0.5</size>
            </box>
          </geometry>
          <material>
            <script>
              <name>Gazebo/Green</name>
              <uri>file://media/materials/scripts/gazebo.material</uri>
            </script>
          </material>
        </visual>
        <self_collide>0</self_collide>
        <enable_wind>0</enable_wind>
        <kinematic>0</kinematic>
      </link>
      <joint name='left_wheel_joint' type='revolute'>
        <pose relative_to='chassis_link'>-0.75 0 -0.375 0 -0 0</pose>
        <parent>chassis_link</parent>
        <child>left_wheel_link</child>
        <axis>
          <xyz>0 0 1</xyz>
          <limit>
            <lower>-3.14e+09</lower>
            <upper>3.14e+09</upper>
            <effort>100</effort>
            <velocity>100</velocity>
          </limit>
          <dynamics>
            <spring_reference>0</spring_reference>
            <spring_stiffness>0</spring_stiffness>
          </dynamics>
        </axis>
      </joint>
      <link name='left_wheel_link'>
        <pose relative_to='left_wheel_joint'>0 0 0 0 -0 0</pose>
        <inertial>
          <pose>0 0 0 1.57 -0 1.57</pose>
          <mass>1</mass>
          <inertia>
            <ixx>0.0182292</ixx>
            <ixy>0</ixy>
            <ixz>0</ixz>
            <iyy>0.0182292</iyy>
            <iyz>0</iyz>
            <izz>0.015625</izz>
          </inertia>
        </inertial>
        <collision name='left_wheel_link_collision'>
          <pose>0 0 0 0 -0 0</pose>
          <geometry>
            <cylinder>
              <length>0.25</length>
              <radius>0.5</radius>
            </cylinder>
          </geometry>
          <surface>
            <friction>
              <ode>
                <mu>15</mu>
                <mu2>15</mu2>
              </ode>
              <torsional>
                <coefficient>20000</coefficient>
              </torsional>
            </friction>
            <contact>
              <ode>
                <min_depth>0.003</min_depth>
              </ode>
            </contact>
            <bounce/>
          </surface>
          <max_contacts>10</max_contacts>
        </collision>
        <visual name='left_wheel_link_visual'>
          <pose>0 0 0 0 -0 0</pose>
          <geometry>
            <cylinder>
              <length>0.25</length>
              <radius>0.5</radius>
            </cylinder>
          </geometry>
          <material>
            <script>
              <name>Gazebo/Orange</name>
              <uri>file://media/materials/scripts/gazebo.material</uri>
            </script>
          </material>
        </visual>
        <self_collide>0</self_collide>
        <enable_wind>0</enable_wind>
        <kinematic>0</kinematic>
      </link>
      <joint name='right_wheel_joint' type='revolute'>
        <pose relative_to='chassis_link'>0.75 0 -0.375 0 -0 0</pose>
        <parent>chassis_link</parent>
        <child>right_wheel_link</child>
        <axis>
          <xyz>0 0 1</xyz>
          <limit>
            <lower>-3.14e+09</lower>
            <upper>3.14e+09</upper>
            <effort>100</effort>
            <velocity>100</velocity>
          </limit>
          <dynamics>
            <spring_reference>0</spring_reference>
            <spring_stiffness>0</spring_stiffness>
          </dynamics>
        </axis>
      </joint>
      <link name='right_wheel_link'>
        <pose relative_to='right_wheel_joint'>0 0 0 0 -0 0</pose>
        <inertial>
          <pose>0 0 0 1.57 -0 1.57</pose>
          <mass>1</mass>
          <inertia>
            <ixx>0.0182292</ixx>
            <ixy>0</ixy>
            <ixz>0</ixz>
            <iyy>0.0182292</iyy>
            <iyz>0</iyz>
            <izz>0.015625</izz>
          </inertia>
        </inertial>
        <collision name='right_wheel_link_collision'>
          <pose>0 0 0 0 -0 0</pose>
          <geometry>
            <cylinder>
              <length>0.25</length>
              <radius>0.5</radius>
            </cylinder>
          </geometry>
          <surface>
            <friction>
              <ode>
                <mu>15</mu>
                <mu2>15</mu2>
              </ode>
              <torsional>
                <coefficient>20000</coefficient>
              </torsional>
            </friction>
            <contact>
              <ode>
                <min_depth>0.003</min_depth>
              </ode>
            </contact>
            <bounce/>
          </surface>
          <max_contacts>10</max_contacts>
        </collision>
        <visual name='right_wheel_link_visual'>
          <pose>0 0 0 0 -0 0</pose>
          <geometry>
            <cylinder>
              <length>0.25</length>
              <radius>0.5</radius>
            </cylinder>
          </geometry>
          <material>
            <script>
              <name>Gazebo/Blue</name>
              <uri>file://media/materials/scripts/gazebo.material</uri>
            </script>
          </material>
        </visual>
        <self_collide>0</self_collide>
        <enable_wind>0</enable_wind>
        <kinematic>0</kinematic>
      </link>
      <plugin name='gazebo_ros_joint_state_publisher' filename='libgazebo_ros_joint_state_publisher.so'>
        <update_rate>50</update_rate>
        <joint_name>chassis_joint</joint_name>
        <joint_name>right_wheel_joint</joint_name>
        <joint_name>left_wheel_joint</joint_name>
      </plugin>
      <plugin name='gazebo_ros_joint_pose_trajectory' filename='libgazebo_ros_joint_pose_trajectory.so'>
        <update_rate>50</update_rate>
      </plugin>
      <static>0</static>
      <plugin name='gazebo_ros2_control' filename='libgazebo_ros2_control.so'>
        <parameters>/home/bluetech/ros2_ws/install/bluetech_simulation/share/bluetech_simulation/config/my_controllers.yaml</parameters>
      </plugin>
      <pose>0 0 0 0 -0 0</pose>

      <plugin name='vacuum_gripper' filename='libgazebo_ros_vacuum_gripper.so'>
        <ros>
          <namespace>/demo</namespace>
          <remapping>switch:=switch_demo</remapping>
          <remapping>grasping:=grasping_demo</remapping>
        </ros>
        <link_name>chassis_link</link_name>
        <max_distance>5.0</max_distance>
        <fixed>ground_plane</fixed>
      </plugin>

    </model>

    <model name='unit_box'>
      <pose>5.5 0 1 0 -0 0</pose>
      <link name='link'>
        <inertial>
          <mass>1</mass>
          <inertia>
            <ixx>0.166667</ixx>
            <ixy>0</ixy>
            <ixz>0</ixz>
            <iyy>0.166667</iyy>
            <iyz>0</iyz>
            <izz>0.166667</izz>
          </inertia>
          <pose>0 0 0 0 -0 0</pose>
        </inertial>
        <collision name='collision'>
          <geometry>
            <box>
              <size>1 1 1</size>
            </box>
          </geometry>
          <max_contacts>10</max_contacts>
          <surface>
            <contact>
              <ode />
            </contact>
            <bounce />
            <friction>
              <ode>
                <mu>1</mu>
                <mu2>1</mu2>
              </ode>
              <torsional>
                <ode />
              </torsional>
              <ode />
            </friction>
          </surface>
        </collision>
        <visual name='visual'>
          <geometry>
            <box>
              <size>1 1 1</size>
            </box>
          </geometry>
          <material>
            <script>
              <name>Gazebo/Orange</name>
              <uri>file://media/materials/scripts/gazebo.material</uri>
            </script>
          </material>
        </visual>
        <self_collide>0</self_collide>
        <enable_wind>0</enable_wind>
        <kinematic>0</kinematic>
      </link>
    </model>
    <!-- <state world_name='default'>
      <sim_time>25 453000000</sim_time>
      <real_time>25 749377920</real_time>
      <wall_time>1666983159 875808064</wall_time>
      <iterations>25453</iterations>
      <model name='bluetech_robot'>
        <pose>0.002462 -0.008594 0.499998 2e-06 -0 0.004863</pose>
        <scale>1 1 1</scale>
        <link name='chassis_link'>
          <pose>0.002462 -0.008594 0.499998 2e-06 -0 0.004863</pose>
          <velocity>-1.9e-05 0.000123 0.000125 -0.000244 1.5e-05 -4.3e-05</velocity>
          <acceleration>-0.077762 0.108335 0.154865 -0.189443 -0.131494 0.037814</acceleration>
          <wrench>-0.077762 0.108335 0.154865 0 -0 0</wrench>
        </link>
        <link name='left_wheel_link'>
          <pose>-0.747529 -0.012241 0.124998 -4e-06 1e-06 -0.015576</pose>
          <velocity>-3.2e-05 6.4e-05 0.000172 -0.000511 -0.000253 0</velocity>
          <acceleration>-0.035544 0.009482 0.091543 -0.453714 -0.398743 0.081004</acceleration>
          <wrench>-0.017772 0.004741 0.045771 0 -0 0</wrench>
        </link>
        <link name='right_wheel_link'>
          <pose>0.752453 -0.004946 0.124999 -3e-06 -0 0.005596</pose>
          <velocity>-3.3e-05 2.7e-05 5.1e-05 -0.000213 -0.000262 0</velocity>
          <acceleration>-0.037379 0.093871 0.18999 -0.157593 -0.408807 0.081055</acceleration>
          <wrench>-0.01869 0.046935 0.094995 0 -0 0</wrench>
        </link>
      </model>
      <model name='ground_plane'>
        <pose>0 0 0 0 -0 0</pose>
        <scale>1 1 1</scale>
        <link name='link'>
          <pose>0 0 0 0 -0 0</pose>
          <velocity>0 0 0 0 -0 0</velocity>
          <acceleration>0 0 0 0 -0 0</acceleration>
          <wrench>0 0 0 0 -0 0</wrench>
        </link>
      </model>
      <light name='sun'>
        <pose>0 0 10 0 -0 0</pose>
      </light>
    </state> -->
    <gui fullscreen='0'>
      <camera name='user_camera'>
        <pose>2.56336 -1.49255 1.84205 -0 0.675643 2.46819</pose>
        <view_controller>orbit</view_controller>
        <projection_type>perspective</projection_type>
      </camera>
    </gui>
  </world>
</sdf>
